Workbook

Sheet Inputs - Flow Network
B1: Keyword: POOL | C1: Name | D1: ASU(Integer ID) | E1: Curve_Type(Name) [retention] | F1: Curve_Type(Name) [decay] | G1: ASU_ Group(Name) [retention] | H1: ASU_Group(Name) [decay] | I1: Max Capacity | J1: Allow Age Zero Flowthrough | K1: Pool_Ruleset(Name) | L1: Description/Note
B3: POOL | C3: Roundwood Harvested, DK | D3: ='Inputs - Spatial'!$C$2 -> 45 | J3: TRUE
B4: POOL | C4: Roundwood Consumed, DK | D4: ='Inputs - Spatial'!$C$2 -> 45 | J4: TRUE
B5: POOL | C5: Roundwood Exported, DK | D5: ='Inputs - Spatial'!$C$2 -> 45 | J5: TRUE
B7: POOL | C7: Sawmill, DK | D7: ='Inputs - Spatial'!$C$2 -> 45
B8: POOL | C8: Sawnwood Produced, DK | D8: ='Inputs - Spatial'!$C$2 -> 45
B9: POOL | C9: Sawnwood Comsumed, DK | D9: ='Inputs - Spatial'!$C$2 -> 45 | E9: IPCC default-sawnwood
B11: POOL | C11: Panel mill, DK | D11: ='Inputs - Spatial'!$C$2 -> 45
B12: POOL | C12: Panel Produced, DK | D12: ='Inputs - Spatial'!$C$2 -> 45
B13: POOL | C13: Panel Consumed, DK | D13: ='Inputs - Spatial'!$C$2 -> 45 | E13: IPCC default-panels
B15: POOL | C15: Milling residues, DK | D15: ='Inputs - Spatial'!$C$2 -> 45
B17: POOL | C17: Paper and Paperboard Produced, DK | D17: ='Inputs - Spatial'!$C$2 -> 45
B18: POOL | C18: Paper and Paperboard Consumed, DK | D18: ='Inputs - Spatial'!$C$2 -> 45 | E18: IPCC default-paper
B20: POOL | C20: Products Exported, DK | D20: ='Inputs - Spatial'!$C$2 -> 45
B22: POOL | C22: CO2, DK | D22: ='Inputs - Spatial'!$C$2 -> 45
B23: POOL | C23: CH4, DK | D23: ='Inputs - Spatial'!$C$2 -> 45
B24: POOL | C24: Other gases, DK | D24: ='Inputs - Spatial'!$C$2 -> 45
B26: Keyword: EVENT | C26: Name | D26: Action_Type(Name) | E26: ASU(Integer ID) | F26: Curve(Name)[Quantity Cap]* | G26: Curve(Name)[Target Quantity]* | H26: First Timestep | I26: Last Timestep | J26: Event Ruleset(Name) | K26: ASU_Group(Name) | L26: Description/Note
B28: EVENT | C28: Roundwood Trading, DK | D28: =C40 -> Roundwood Trading | E28: ='Inputs - Spatial'!$C$2 -> 45
B29: EVENT | C29: Roundwood value-adding, DK | D29: =C41 -> Roundwood breakdown | E29: ='Inputs - Spatial'!$C$2 -> 45
B30: EVENT | C30: Sawnwood manufacturing, DK | D30: =C42 -> Sawmilling | E30: ='Inputs - Spatial'!$C$2 -> 45
B31: EVENT | C31: Panel manufacturing, DK | D31: =C43 -> Panel Manufacturing | E31: ='Inputs - Spatial'!$C$2 -> 45
B32: EVENT | C32: ="Pulp and Paper manufacturing, "&'Inputs - Spatial'!C10 -> Pulp and Paper manufacturing, DK | D32: =C44 -> Pulping | E32: ='Inputs - Spatial'!$C$2 -> 45
B33: EVENT | C33: Sawnwood Trading, DK | D33: =C45 -> Sawnwood Trading | E33: ='Inputs - Spatial'!$C$2 -> 45
B34: EVENT | C34: Panel Trading, DK | D34: =C46 -> Panel Trading | E34: ='Inputs - Spatial'!$C$2 -> 45
B35: EVENT | C35: Paper and Paperboard Trading, DK | D35: =C47 -> Paper Trading | E35: ='Inputs - Spatial'!$C$2 -> 45
B36: EVENT | C36: End of Life Processing, DK | D36: =C48 -> End of Life Practice | E36: ='Inputs - Spatial'!$C$2 -> 45
B38: Keyword: ACTION_TYPE | C38: NAME
B40: ACTION_TYPE | C40: Roundwood Trading
B41: ACTION_TYPE | C41: Roundwood breakdown
B42: ACTION_TYPE | C42: Sawmilling
B43: ACTION_TYPE | C43: Panel Manufacturing
B44: ACTION_TYPE | C44: Pulping
B45: ACTION_TYPE | C45: Sawnwood Trading
B46: ACTION_TYPE | C46: Panel Trading
B47: ACTION_TYPE | C47: Paper Trading
B48: ACTION_TYPE | C48: End of Life Practice
B50: Keyword: EVENT_POOL | C50: Event(Name) | D50: Pool(Name) | E50: Source? | F50: Sequence Number | G50: Allow Recycling (Boolean)
B52: EVENT_POOL | C52: {=$C$28} -> Roundwood Trading, DK | D52: {=$C3} -> Roundwood Harvested, DK | E52: TRUE | F52: 1
B53: EVENT_POOL | C53: {=$C$28} -> Roundwood Trading, DK | D53: {=C4} -> Roundwood Consumed, DK | E53: FALSE | F53: 1
...

Sheet Inputs - Carbon Mass
B1: Keyword: INITIAL_CMO | C1: Entry Pool (Pool Name) | D1: Species (Name) | E1: Physical State (Name) | F1: Quantity (Double precison) | G1: Entry Time Step (Integer) | H1: Empty Field | I1: Empty Field | J1: Empty Field | K1: Description
B3: INITIAL_CMO | C3: ='Inputs - Flow Network'!C3 -> Roundwood Harvested, DK | E3: ='Inputs - Categorical'!C3 -> Roundwood | F3: 100 | G3: 1

Sheet Inputs - Categorical
B1: Keyword: PHYSICAL_STATE | C1: Name | D1: Description
B3: PHYSICAL_STATE | C3: Roundwood
B5: Keyword: PHYSICAL_STATE_GROUP | C5: Name | D5: Reference | E5: Description
B7: Keyword: PHYSICAL_STATE_GROUP_MEMBER | C7: Group(Name) | D7: Physical_State(Name)
B9: Keyword: SPECIES | C9: Name | D9: Alternate_Name | E9: Code | F9: Reference | G9: Description
B11: Keyword: SPECIES_GROUP | C11: Name | D11: Reference | E11: Description
B13: Keyword: SPECIES_GROUP_MEMBER | C13: Species_Group(Name) | D13: Species(Name)
B15: Keyword: TAG | C15: Name | D15: Value | E15: Description

Sheet Inputs - Spatial
B1: Keyword: ASU | C1: ID | D1: Name | E1: Area | F1: Tag(Name) | G1: GIS_Id | H1: Description
B2: ASU | C2: 45 | D2: DK | E2: 1
B5: Keyword: ASU_GROUP_TYPE | C5: Name
B6: ASU_GROUP_TYPE | C6: Nation
B8: Keyword: ASU_GROUP | C8: Name | D8: ASU_Group_Type(Name) | E8: Description
B10: ASU_GROUP | C10: DK | D10: =C6 -> Nation
B12: Keyword: ASU_GROUP_MEMBER | C12: ASU_Group(Name) | D12: ASU(ID) | E12: Includes: ASU_Group(Name)
B13: ASU_GROUP_MEMBER | C13: =C10 -> DK | D13: =C2 -> 45

Sheet Inputs - Curves
B1: Keyword: CURVE | C1: Name | D1: Usage | E1: Reference | F1: Description
B3: Keyword: CURVE_TYPE | C3: Name | D3: Reference | E3: Description
B5: Keyword: CURVE_TYPE_MEMBER | C5: Curve_Type(Name) | D5: Curve(Name) | E5: ASU_Group(Name) | F5: Effective start timestep
B7: Keyword: CURVE_POINT | C7: Curve(Name) | D7: X_axis (Independent Variable) | E7: Y_axis (Dependent Variable)
