Workbook

Sheet Inputs - Flow Network
B1: Keyword: POOL | C1: Name | D1: ASU(Integer ID) | E1: Curve_Type(Name) [retention] | F1: Curve_Type(Name) [decay] | G1: ASU_ Group(Name) [retention] | H1: ASU_Group(Name) [decay] | I1: Max Capacity | J1: Allow Age Zero Flowthrough | K1: Pool_Ruleset(Name) | L1: Description/Note
B3: POOL | C3: ="Structural building materials, "&'Inputs - Spatial'!$C$10 -> Structural building materials, CA | D3: ='Inputs - Spatial'!$C$2 -> 1
B4: POOL | C4: ="Residential Dwellings, "&'Inputs - Spatial'!$C$10 -> Residential Dwellings, CA | D4: ='Inputs - Spatial'!$C$2 -> 1 | E4: ='Inputs - Advanced Curves'!$C$9 -> US Residential Gamma Retention
B5: POOL | C5: ="Repair & Remodeling, "&'Inputs - Spatial'!$C$10 -> Repair & Remodeling, CA | D5: ='Inputs - Spatial'!$C$2 -> 1 | E5: ='Inputs - Advanced Curves'!$C$9 -> US Residential Gamma Retention
B6: POOL | C6: ="Non-residential building, "&'Inputs - Spatial'!$C$10 -> Non-residential building, CA | D6: ='Inputs - Spatial'!$C$2 -> 1 | E6: ='Inputs - Advanced Curves'!$C$9 -> US Residential Gamma Retention
B8: POOL | C8: ="Other Structural Uses, "&'Inputs - Spatial'!$C$10 -> Other Structural Uses, CA | D8: ='Inputs - Spatial'!$C$2 -> 1 | E8: ='Inputs - Advanced Curves'!$C$9 -> US Residential Gamma Retention
B10: POOL | C10: ="CO2, "&'Inputs - Spatial'!$C$10 -> CO2, CA | D10: ='Inputs - Spatial'!$C$2 -> 1
B12: Keyword: EVENT | C12: Name | D12: Action_Type(Name) | E12: ASU(Integer ID) | F12: Curve(Name)[Quantity Cap]* | G12: Curve(Name)[Target Quantity]* | H12: First Timestep | I12: Last Timestep | J12: Event Ruleset(Name) | K12: ASU_Group(Name) | L12: Description/Note
B14: EVENT | C14: ="Construction Demand, "&'Inputs - Spatial'!C10 -> Construction Demand, CA | D14: =C20 -> Manufacturing | E14: ='Inputs - Spatial'!$C$2 -> 1
B15: EVENT | C15: ="Landfilling, "&'Inputs - Spatial'!$C$10 -> Landfilling, CA | D15: =C21 -> Landfilling | E15: ='Inputs - Spatial'!$C$2 -> 1
B16: EVENT | C16: ="Combusting, "&'Inputs - Spatial'!$C$10 -> Combusting, CA | D16: =C22 -> Combusting | E16: ='Inputs - Spatial'!$C$2 -> 1
B18: Keyword: ACTION_TYPE | C18: NAME
B20: ACTION_TYPE | C20: Manufacturing
B21: ACTION_TYPE | C21: Landfilling
B22: ACTION_TYPE | C22: Combusting
B25: Keyword: EVENT_POOL | C25: Event(Name) | D25: Pool(Name) | E25: Source? | F25: Sequence Number | G25: Allow Recycling (Boolean)
B27: EVENT_POOL | C27: =$C$14 -> Construction Demand, CA | D27: =C3 -> Structural building materials, CA | E27: TRUE | F27: 1
B28: EVENT_POOL | C28: =$C$14 -> Construction Demand, CA | D28: =C4 -> Residential Dwellings, CA | E28: FALSE | F28: 1
B29: EVENT_POOL | C29: =$C$14 -> Construction Demand, CA | D29: =C5 -> Repair & Remodeling, CA | E29: FALSE | F29: 2
B30: EVENT_POOL | C30: =$C$14 -> Construction Demand, CA | D30: =C6 -> Non-residential building, CA | E30: FALSE | F30: 3
B31: EVENT_POOL | C31: =$C$14 -> Construction Demand, CA | D31: =C8 -> Other Structural Uses, CA | E31: FALSE | F31: 4
B33: EVENT_POOL | C33: {=$C$15} -> Landfilling, CA | D33: =C4 -> Residential Dwellings, CA | E33: TRUE | F33: 1
B34: EVENT_POOL | C34: {=$C$15} -> Landfilling, CA | D34: =C5 -> Repair & Remodeling, CA | E34: TRUE | F34: 2
B35: EVENT_POOL | C35: {=$C$15} -> Landfilling, CA | D35: =C6 -> Non-residential building, CA | E35: TRUE | F35: 3
B36: EVENT_POOL | C36: {=$C$15} -> Landfilling, CA | D36: =C10 -> CO2, CA | E36: FALSE | F36: 1
B38: EVENT_POOL | C38: =$C$16 -> Combusting, CA | D38: =C8 -> Other Structural Uses, CA | E38: TRUE | F38: 1
B39: EVENT_POOL | C39: =$C$16 -> Combusting, CA | D39: =C10 -> CO2, CA | E39: FALSE | F39: 1
B41: Keyword: ACTION_PARAMETER_SET | C41: Name | D41: Action_Type (Name) | E41: ASU_Group(Name) | F41: Effective Start Timestep* | G41: Reference | H41: Description
B43: ACTION_PARAMETER_SET | C43: ="Commodity Demand, "&'Inputs - Spatial'!$C$10 -> Commodity Demand, CA | D43: =C20 -> Manufacturing | E43: ='Inputs - Spatial'!$C$10 -> CA
B44: ACTION_PARAMETER_SET | C44: ="Landfill Parameters, "&'Inputs - Spatial'!$C$10 -> Landfill Parameters, CA | D44: =C21 -> Landfilling | E44: ='Inputs - Spatial'!$C$10 -> CA
B45: ACTION_PARAMETER_SET | C45: ="Combustion Parameters, "&'Inputs - Spatial'!$C$10 -> Combustion Parameters, CA | D45: =C22 -> Combusting | E45: ='Inputs - Spatial'!$C$10 -> CA
B47: Keyword: ACTION_PARAMETER_OUT | C47: Action_Parameter_Set(Name) | D47: Sequence Number | E47: Proportion | F47: Target | G47: New Physical State Name | H47: Physical State Rule | I47: Species Rule | J47: Note
B49: ACTION_PARAMETER_OUT | C49: =$C$43 -> Commodity Demand, CA | D49: =F28 -> 1 | F49: 30
B50: ACTION_PARAMETER_OUT | C50: =$C$43 -> Commodity Demand, CA | D50: =F29 -> 2 | F50: 10
B51: ACTION_PARAMETER_OUT | C51: =$C$43 -> Commodity Demand, CA | D51: =F30 -> 3 | F51: 20
B52: ACTION_PARAMETER_OUT | C52: =$C$43 -> Commodity Demand, CA | D52: =F31 -> 4 | F52: 0
B54: ACTION_PARAMETER_OUT | C54: =$C$43 -> Commodity Demand, CA | D54: =F28 -> 1 | E54: 0
B55: ACTION_PARAMETER_OUT | C55: =$C$43 -> Commodity Demand, CA | D55: =F29 -> 2 | E55: 0
B56: ACTION_PARAMETER_OUT | C56: =$C$43 -> Commodity Demand, CA | D56: =F30 -> 3 | E56: 0
B57: ACTION_PARAMETER_OUT | C57: =$C$43 -> Commodity Demand, CA | D57: =F31 -> 4 | E57: 1
...

Sheet Inputs - Carbon Mass
B1: Keyword: INITIAL_CMO | C1: Entry Pool (Pool Name) | D1: Species (Name) | E1: Physical State (Name) | F1: Quantity (Double precison) | G1: Entry Time Step (Integer) | H1: Initial Age | I1: Tag (Name) | J1: Is Retained | K1: Description
B2: INITIAL_CMO | C2: ='Inputs - Flow Network'!$C$3 -> Structural building materials, CA | F2: 100 | G2: 1

Sheet Inputs - Categorical
B1: Keyword: PHYSICAL_STATE | C1: Name | D1: Description
B3: PHYSICAL_STATE | C3: Roundwood
B4: PHYSICAL_STATE | C4: Sawnwood
B5: PHYSICAL_STATE | C5: Panels
B6: PHYSICAL_STATE | C6: Paper
B7: PHYSICAL_STATE | C7: Bioenergy
B9: Keyword: PHYSICAL_STATE_GROUP | C9: Name | D9: Reference | E9: Description
B11: Keyword: PHYSICAL_STATE_GROUP_MEMBER | C11: Group(Name) | D11: Physical_State(Name)
B13: Keyword: SPECIES | C13: Name | D13: Alternate_Name | E13: Code | F13: Reference | G13: Description
B15: SPECIES | C15: Softwood
B16: SPECIES | C16: Hardwood
B18: Keyword: SPECIES_GROUP | C18: Name | D18: Reference | E18: Description
B20: Keyword: SPECIES_GROUP_MEMBER | C20: Species_Group(Name) | D20: Species(Name)
B22: Keyword: TAG | C22: Name | D22: Value | E22: Description

Sheet Inputs - Spatial
B1: Keyword: ASU | C1: ID | D1: Name | E1: Area | F1: Tag(Name) | G1: GIS_Id | H1: Description
B2: ASU | C2: 1 | D2: CA | E2: 998
B5: Keyword: ASU_GROUP_TYPE | C5: Name
B6: ASU_GROUP_TYPE | C6: Nation
B8: Keyword: ASU_GROUP | C8: Name | D8: ASU_Group_Type(Name) | E8: Description
B10: ASU_GROUP | C10: CA | D10: =C6 -> Nation
B13: Keyword: ASU_GROUP_MEMBER | C13: ASU_Group(Name) | D13: ASU(ID) | E13: Includes: ASU_Group(Name)
B14: ASU_GROUP_MEMBER | C14: =C10 -> CA | D14: =C2 -> 1

Sheet Inputs - Advanced Curves
B1: Keyword: CURVE | C1: Name | D1: Usage | E1: Reference | F1: Description
B3: CURVE | C3: Gamma (2.07 80.2) | D3: initial | E3: Xie, 2015
B7: Keyword: CURVE_TYPE | C7: Name | D7: Reference | E7: Description
B9: CURVE_TYPE | C9: US Residential Gamma Retention
B12: Keyword: CURVE_TYPE_MEMBER | C12: Curve_Type(Name) | D12: Curve(Name) | E12: ASU_Group(Name) | F12: Effective start timestep
B14: CURVE_TYPE_MEMBER | C14: =C9 -> US Residential Gamma Retention | D14: =C3 -> Gamma (2.07 80.2) | E14: UNIVERSE | F14: 1
B19: Keyword: CURVE_POINT | C19: Curve(Name) | D19: X_axis (Independent Variable) | E19: Y_axis (Dependent Variable)
B21: CURVE_POINT | C21: =$C$3 -> Gamma (2.07 80.2) | D21: 0 | E21: 1
B22: CURVE_POINT | C22: =$C$3 -> Gamma (2.07 80.2) | D22: 1 | E22: 0.99994689
B23: CURVE_POINT | C23: =$C$3 -> Gamma (2.07 80.2) | D23: 2 | E23: 0.99977885
B24: CURVE_POINT | C24: =$C$3 -> Gamma (2.07 80.2) | D24: 3 | E24: 0.99949235
B25: CURVE_POINT | C25: =$C$3 -> Gamma (2.07 80.2) | D25: 4 | E25: 0.99908684
B26: CURVE_POINT | C26: =$C$3 -> Gamma (2.07 80.2) | D26: 5 | E26: 0.9985628
B27: CURVE_POINT | C27: =$C$3 -> Gamma (2.07 80.2) | D27: 6 | E27: 0.9979213
B28: CURVE_POINT | C28: =$C$3 -> Gamma (2.07 80.2) | D28: 7 | E28: 0.99716376
B29: CURVE_POINT | C29: =$C$3 -> Gamma (2.07 80.2) | D29: 8 | E29: 0.9962918
B30: CURVE_POINT | C30: =$C$3 -> Gamma (2.07 80.2) | D30: 9 | E30: 0.99530724
B31: CURVE_POINT | C31: =$C$3 -> Gamma (2.07 80.2) | D31: 10 | E31: 0.99421198
B32: CURVE_POINT | C32: =$C$3 -> Gamma (2.07 80.2) | D32: 11 | E32: 0.99300802
... B321: CURVE_POINT | C321: =$C$3 -> Gamma (2.07 80.2) | D321: 300 | E321: 0.1218235
