Workbook

Sheet Inputs - Flow Network
B1: Keyword: POOL | C1: Name | D1: ASU(Integer ID) | E1: Curve_Type(Name) [retention] | F1: Curve_Type(Name) [decay] | G1: ASU_ Group(Name) [retention] | H1: ASU_Group(Name) [decay] | I1: Max Capacity | J1: Allow Age Zero Flowthrough | K1: Pool_Ruleset(Name) | L1: Description/Note
B3: POOL | C3: Sawnwood | E3: IPCC default-sawnwood
B4: POOL | C4: Panels | E4: IPCC default-panels
B5: POOL | C5: Paper | E5: IPCC default-paper
B7: POOL | C7: CO2
B9: Keyword: EVENT | C9: Name | D9: Action_Type(Name) | E9: ASU(Integer ID) | F9: Curve(Name)[Quantity Cap]* | G9: Curve(Name)[Target Quantity]* | H9: First Timestep | I9: Last Timestep | J9: Event Ruleset(Name) | K9: ASU_Group(Name) | L9: Description/Note
B11: EVENT | C11: Landfilling
B13: Keyword: EVENT_POOL | C13: Event(Name) | D13: Pool(Name) | E13: Source? | F13: Sequence Number | G13: Allow Recycling (Boolean)
B15: EVENT_POOL | C15: {=$C$11} -> Landfilling | D15: =C3 -> Sawnwood | E15: =TRUE() -> TRUE | F15: 1
B16: EVENT_POOL | C16: {=$C$11} -> Landfilling | D16: =C4 -> Panels | E16: =TRUE() -> TRUE | F16: 2
B17: EVENT_POOL | C17: {=$C$11} -> Landfilling | D17: =C5 -> Paper | E17: =TRUE() -> TRUE | F17: 3
B18: EVENT_POOL | C18: {=$C$11} -> Landfilling | D18: =C7 -> CO2 | E18: =FALSE() -> FALSE | F18: 1
B20: Keyword: ACTION_PARAMETER_OUT | C20: Action_Parameter_Set | D20: Sequence Number | E20: Proportion | F20: Target | G20: New Physical State Name | H20: Physical State Rule | I20: Species Rule | J20: Note
B22: ACTION_PARAMETER_OUT | C22: =C18 -> Landfilling | D22: 1 | E22: 1

Sheet Inputs - Carbon Mass
B1: Keyword: INITIAL_CMO | C1: Entry Pool (Pool Name) | D1: Species (Name) | E1: Physical State (Name) | F1: Quantity (Double precison) | G1: Entry Time Step (Integer) | H1: Initial Age | I1: Tag (Name) | J1: Is Retained | K1: Description
B3: INITIAL_CMO | C3: ='Inputs - Flow Network'!$C$3 -> Sawnwood | F3: 30 | G3: 1 | J3: TRUE
B4: INITIAL_CMO | C4: ='Inputs - Flow Network'!$C$4 -> Panels | F4: 10 | G4: 1 | J4: TRUE
B5: INITIAL_CMO | C5: ='Inputs - Flow Network'!$C$5 -> Paper | F5: 40 | G5: 1 | J5: TRUE
A7: COMMENT | B7: INITIAL_CMO | C7: ='Inputs - Flow Network'!$C$3 -> Sawnwood | F7: 503342 | G7: 1 | J7: =TRUE() -> TRUE | K7: 1990
A8: COMMENT | B8: INITIAL_CMO | C8: ='Inputs - Flow Network'!$C$3 -> Sawnwood | F8: 518227 | G8: 2 | J8: =TRUE() -> TRUE | K8: 1991
A9: COMMENT | B9: INITIAL_CMO | C9: ='Inputs - Flow Network'!$C$3 -> Sawnwood | F9: 582576 | G9: 3 | J9: =TRUE() -> TRUE | K9: 1992
A10: COMMENT | B10: INITIAL_CMO | C10: ='Inputs - Flow Network'!$C$3 -> Sawnwood | F10: 642345 | G10: 4 | J10: =TRUE() -> TRUE | K10: 1993
A11: COMMENT | B11: INITIAL_CMO | C11: ='Inputs - Flow Network'!$C$3 -> Sawnwood | F11: 655169 | G11: 5 | J11: =TRUE() -> TRUE | K11: 1994
A12: COMMENT | B12: INITIAL_CMO | C12: ='Inputs - Flow Network'!$C$3 -> Sawnwood | F12: 675550 | G12: 6 | J12: =TRUE() -> TRUE | K12: 1995
A13: COMMENT | B13: INITIAL_CMO | C13: ='Inputs - Flow Network'!$C$3 -> Sawnwood | F13: 694328 | G13: 7 | J13: =TRUE() -> TRUE | K13: 1996
A14: COMMENT | B14: INITIAL_CMO | C14: ='Inputs - Flow Network'!$C$3 -> Sawnwood | F14: 718144 | G14: 8 | J14: =TRUE() -> TRUE | K14: 1997
A15: COMMENT | B15: INITIAL_CMO | C15: ='Inputs - Flow Network'!$C$3 -> Sawnwood | F15: 727762 | G15: 9 | J15: =TRUE() -> TRUE | K15: 1998
A16: COMMENT | B16: INITIAL_CMO | C16: ='Inputs - Flow Network'!$C$3 -> Sawnwood | F16: 836537 | G16: 10 | J16: =TRUE() -> TRUE | K16: 1999
A17: COMMENT | B17: INITIAL_CMO | C17: ='Inputs - Flow Network'!$C$3 -> Sawnwood | F17: 895390 | G17: 11 | J17: =TRUE() -> TRUE | K17: 2000
A18: COMMENT | B18: INITIAL_CMO | C18: ='Inputs - Flow Network'!$C$3 -> Sawnwood | F18: 875009 | G18: 12 | J18: =TRUE() -> TRUE | K18: 2001
... A41: COMMENT | B41: INITIAL_CMO | C41: ='Inputs - Flow Network'!$C$3 -> Sawnwood | F41: 950423.51 | G41: 35 | J41: =TRUE() -> TRUE | K41: 2024
A43: COMMENT | B43: INITIAL_CMO | C43: ='Inputs - Flow Network'!$C$4 -> Panels | F43: 183727 | G43: 1 | J43: =TRUE() -> TRUE | K43: 1990
A44: COMMENT | B44: INITIAL_CMO | C44: ='Inputs - Flow Network'!$C$4 -> Panels | F44: 194487 | G44: 2 | J44: =TRUE() -> TRUE | K44: 1991
A45: COMMENT | B45: INITIAL_CMO | C45: ='Inputs - Flow Network'!$C$4 -> Panels | F45: 206592 | G45: 3 | J45: =TRUE() -> TRUE | K45: 1992
A46: COMMENT | B46: INITIAL_CMO | C46: ='Inputs - Flow Network'!$C$4 -> Panels | F46: 221656 | G46: 4 | J46: =TRUE() -> TRUE | K46: 1993
A47: COMMENT | B47: INITIAL_CMO | C47: ='Inputs - Flow Network'!$C$4 -> Panels | F47: 259047 | G47: 5 | J47: =TRUE() -> TRUE | K47: 1994
A48: COMMENT | B48: INITIAL_CMO | C48: ='Inputs - Flow Network'!$C$4 -> Panels | F48: 266848 | G48: 6 | J48: =TRUE() -> TRUE | K48: 1995
A49: COMMENT | B49: INITIAL_CMO | C49: ='Inputs - Flow Network'!$C$4 -> Panels | F49: 250708 | G49: 7 | J49: =TRUE() -> TRUE | K49: 1996
A50: COMMENT | B50: INITIAL_CMO | C50: ='Inputs - Flow Network'!$C$4 -> Panels | F50: 274649 | G50: 8 | J50: =TRUE() -> TRUE | K50: 1997
A51: COMMENT | B51: INITIAL_CMO | C51: ='Inputs - Flow Network'!$C$4 -> Panels | F51: 248287 | G51: 9 | J51: =TRUE() -> TRUE | K51: 1998
A52: COMMENT | B52: INITIAL_CMO | C52: ='Inputs - Flow Network'!$C$4 -> Panels | F52: 300473 | G52: 10 | J52: =TRUE() -> TRUE | K52: 1999
A53: COMMENT | B53: INITIAL_CMO | C53: ='Inputs - Flow Network'!$C$4 -> Panels | F53: 337595 | G53: 11 | J53: =TRUE() -> TRUE | K53: 2000
A54: COMMENT | B54: INITIAL_CMO | C54: ='Inputs - Flow Network'!$C$4 -> Panels | F54: 341361 | G54: 12 | J54: =TRUE() -> TRUE | K54: 2001
... A77: COMMENT | B77: INITIAL_CMO | C77: ='Inputs - Flow Network'!$C$4 -> Panels | F77: 251212.38 | G77: 35 | J77: =TRUE() -> TRUE | K77: 2024
A79: COMMENT | B79: INITIAL_CMO | C79: ='Inputs - Flow Network'!$C$5 -> Paper | F79: 292202 | G79: 1 | J79: =TRUE() -> TRUE | K79: 1990
A80: COMMENT | B80: INITIAL_CMO | C80: ='Inputs - Flow Network'!$C$5 -> Paper | F80: 314590 | G80: 2 | J80: =TRUE() -> TRUE | K80: 1991
A81: COMMENT | B81: INITIAL_CMO | C81: ='Inputs - Flow Network'!$C$5 -> Paper | F81: 284868 | G81: 3 | J81: =TRUE() -> TRUE | K81: 1992
A82: COMMENT | B82: INITIAL_CMO | C82: ='Inputs - Flow Network'!$C$5 -> Paper | F82: 322696 | G82: 4 | J82: =TRUE() -> TRUE | K82: 1993
A83: COMMENT | B83: INITIAL_CMO | C83: ='Inputs - Flow Network'!$C$5 -> Paper | F83: 333504 | G83: 5 | J83: =TRUE() -> TRUE | K83: 1994
A84: COMMENT | B84: INITIAL_CMO | C84: ='Inputs - Flow Network'!$C$5 -> Paper | F84: 348558 | G84: 6 | J84: =TRUE() -> TRUE | K84: 1995
A85: COMMENT | B85: INITIAL_CMO | C85: ='Inputs - Flow Network'!$C$5 -> Paper | F85: 333890 | G85: 7 | J85: =TRUE() -> TRUE | K85: 1996
A86: COMMENT | B86: INITIAL_CMO | C86: ='Inputs - Flow Network'!$C$5 -> Paper | F86: 343540 | G86: 8 | J86: =TRUE() -> TRUE | K86: 1997
A87: COMMENT | B87: INITIAL_CMO | C87: ='Inputs - Flow Network'!$C$5 -> Paper | F87: 325784 | G87: 9 | J87: =TRUE() -> TRUE | K87: 1998
A88: COMMENT | B88: INITIAL_CMO | C88: ='Inputs - Flow Network'!$C$5 -> Paper | F88: 315362 | G88: 10 | J88: =TRUE() -> TRUE | K88: 1999
...
