Workbook

Sheet Inputs - Flow Network
B1: Keyword: POOL | C1: Name | D1: ASU(Integer ID) | E1: Curve_Type(Name) [retention] | F1: Curve_Type(Name) [decay] | G1: ASU_ Group(Name) [retention] | H1: ASU_Group(Name) [decay] | I1: Max Capacity | J1: Allow Age Zero Flowthrough | K1: Pool_Ruleset(Name) | L1: Description/Note
B3: POOL | C3: Roundwood
B4: POOL | C4: Sawnwood | E4: IPCC default-sawnwood
B5: POOL | C5: Panels | E5: IPCC default-panels
B6: POOL | C6: Paper | E6: IPCC default-paper
B8: POOL | C8: Milling Residue
B10: POOL | C10: Wood pellets
B11: POOL | C11: Other bioenergy
B13: POOL | C13: Waste Incineration
B14: POOL | C14: Solid Waste Disposal Site
B16: POOL | C16: CO2 Emissions
B18: Keyword: EVENT | C18: Name | D18: Action_Type(Name) | E18: ASU(Integer ID) | F18: Curve(Name)[Quantity Cap]* | G18: Curve(Name)[Target Quantity]* | H18: First Timestep | I18: Last Timestep | J18: Event Ruleset(Name) | K18: ASU_Group(Name) | L18: Description/Note
B20: EVENT | C20: Manufacturing
B21: EVENT | C21: Residue Valorizing
B22: EVENT | C22: Combusting
B23: EVENT | C23: Post-consumer Processing
A24: =IF('Inputs - Landfill Module'!$C$3="OFF","","COMMENT") -> COMMENT | B24: EVENT | C24: Landfilling
B25: EVENT | C25: Incinerating
B27: Keyword: ACTION_TYPE | C27: NAME
B29: Keyword: EVENT_POOL | C29: Event(Name) | D29: Pool(Name) | E29: Source? | F29: Sequence Number | G29: Allow Recycling (Boolean)
B31: EVENT_POOL | C31: =$C$20 -> Manufacturing | D31: =C3 -> Roundwood | E31: =TRUE() -> TRUE | F31: 1
B32: EVENT_POOL | C32: =$C$20 -> Manufacturing | D32: =C4 -> Sawnwood | E32: =FALSE() -> FALSE | F32: 1
B33: EVENT_POOL | C33: =$C$20 -> Manufacturing | D33: =C5 -> Panels | E33: =FALSE() -> FALSE | F33: 2
B34: EVENT_POOL | C34: =$C$20 -> Manufacturing | D34: =C6 -> Paper | E34: =FALSE() -> FALSE | F34: 3
B35: EVENT_POOL | C35: =$C$20 -> Manufacturing | D35: =C8 -> Milling Residue | E35: =FALSE() -> FALSE | F35: 4
B37: EVENT_POOL | C37: =$C$21 -> Residue Valorizing | D37: =C8 -> Milling Residue | E37: =TRUE() -> TRUE | F37: 1
B38: EVENT_POOL | C38: =$C$21 -> Residue Valorizing | D38: =C10 -> Wood pellets | E38: =FALSE() -> FALSE | F38: 1
B39: EVENT_POOL | C39: =$C$21 -> Residue Valorizing | D39: =C11 -> Other bioenergy | E39: =FALSE() -> FALSE | F39: 2
B40: EVENT_POOL | C40: =$C$21 -> Residue Valorizing | D40: =C14 -> Solid Waste Disposal Site | E40: =FALSE() -> FALSE | F40: 3
B42: EVENT_POOL | C42: =$C$23 -> Post-consumer Processing | D42: =C4 -> Sawnwood | E42: =TRUE() -> TRUE | F42: 1
B43: EVENT_POOL | C43: =$C$23 -> Post-consumer Processing | D43: =C5 -> Panels | E43: =TRUE() -> TRUE | F43: 2
B44: EVENT_POOL | C44: =$C$23 -> Post-consumer Processing | D44: =C6 -> Paper | E44: =TRUE() -> TRUE | F44: 3
B45: EVENT_POOL | C45: =$C$23 -> Post-consumer Processing | D45: =C13 -> Waste Incineration | E45: =FALSE() -> FALSE | F45: 1
B46: EVENT_POOL | C46: =$C$23 -> Post-consumer Processing | D46: =C14 -> Solid Waste Disposal Site | E46: =FALSE() -> FALSE | F46: 2
A48: =IF('Inputs - Landfill Module'!$C$3="OFF","","COMMENT") -> COMMENT | B48: EVENT_POOL | C48: {=$C$24} -> Landfilling | D48: =D46 -> Solid Waste Disposal Site | E48: =TRUE() -> TRUE | F48: 1
A49: =IF('Inputs - Landfill Module'!$C$3="OFF","","COMMENT") -> COMMENT | B49: EVENT_POOL | C49: {=$C$24} -> Landfilling | D49: =C16 -> CO2 Emissions | E49: =FALSE() -> FALSE | F49: 1
B51: EVENT_POOL | C51: =$C$25 -> Incinerating | D51: =C13 -> Waste Incineration | E51: =TRUE() -> TRUE | F51: 1
B52: EVENT_POOL | C52: =$C$25 -> Incinerating | D52: =C16 -> CO2 Emissions | E52: =FALSE() -> FALSE | F52: 1
B54: EVENT_POOL | C54: =$C$22 -> Combusting | D54: =C10 -> Wood pellets | E54: =TRUE() -> TRUE | F54: 1
B55: EVENT_POOL | C55: =$C$22 -> Combusting | D55: =C11 -> Other bioenergy | E55: =TRUE() -> TRUE | F55: 2
...

Sheet Inputs - Landfill Module
A2: COMMENT | B2: This landfill module can be switched on and off as needed
A3: COMMENT | B3: Landfill Module ON/OFF Switch | C3: ON
B5: Keyword: POOL | C5: Name | D5: ASU(Integer ID) | E5: Curve_Type(Name) [retention] | F5: Curve_Type(Name) [decay] | G5: ASU_ Group(Name) [retention] | H5: ASU_Group(Name) [decay] | I5: Max Capacity | J5: Allow Age Zero Flowthrough | K5: Pool_Ruleset(Name) | L5: Description/Note
A7: =IF($C$3="ON","","COMMENT") | B7: POOL | C7: Aerobic conditions
A8: =IF($C$3="ON","","COMMENT") | B8: POOL | C8: Anaerobic conditions
A9: =IF($C$3="ON","","COMMENT")
A10: =IF($C$3="ON","","COMMENT") | B10: POOL | C10: Decomposable
A11: =IF($C$3="ON","","COMMENT") | B11: POOL | C11: Non-decomposable
A12: =IF($C$3="ON","","COMMENT")
A13: =IF($C$3="ON","","COMMENT") | B13: POOL | C13: Landfilled Wood, Boreal Wet | E13: ='Inputs - Curves'!C8 -> Landfilled Wood Decay Curve
A14: =IF($C$3="ON","","COMMENT") | B14: POOL | C14: Landfilled Paper, Boreal Wet | E14: ='Inputs - Curves'!C9 -> Landfilled Paper Decay Curve
A15: =IF($C$3="ON","","COMMENT")
A16: =IF($C$3="ON","","COMMENT") | B16: POOL | C16: CH4 Generated
A17: =IF($C$3="ON","","COMMENT")
A18: =IF($C$3="ON","","COMMENT") | B18: POOL | C18: Flared CH4
A19: =IF($C$3="ON","","COMMENT") | B19: POOL | C19: CH4-to-energy
A20: =IF($C$3="ON","","COMMENT") | B20: POOL | C20: Unrecovered CH4
A21: =IF($C$3="ON","","COMMENT")
A22: =IF($C$3="ON","","COMMENT") | B22: POOL | C22: CH4 Emissions
B24: Keyword: EVENT | C24: Name | D24: Action_Type(Name) | E24: ASU(Integer ID) | F24: Curve(Name)[Quantity Cap]* | G24: Curve(Name)[Target Quantity]* | H24: First Timestep | I24: Last Timestep | J24: Event Ruleset(Name) | K24: ASU_Group(Name) | L24: Description/Note
A26: =IF($C$3="ON","","COMMENT") | B26: EVENT | C26: MCF Factoring
A27: =IF($C$3="ON","","COMMENT") | B27: EVENT | C27: DOCf Factoring
A28: =IF($C$3="ON","","COMMENT") | B28: EVENT | C28: Climate Zoning
A29: =IF($C$3="ON","","COMMENT") | B29: EVENT | C29: F Factoring
A30: =IF($C$3="ON","","COMMENT") | B30: EVENT | C30: R Factoring
A31: =IF($C$3="ON","","COMMENT") | B31: EVENT | C31: Flaring
A32: =IF($C$3="ON","","COMMENT") | B32: EVENT | C32: CH4 Combusting
A33: =IF($C$3="ON","","COMMENT") | B33: EVENT | C33: OX Factoring
A34: =IF($C$3="ON","","COMMENT") | B34: EVENT | C34: Aerobic Oxidizing
B36: Keyword: ACTION_TYPE | C36: NAME
B38: Keyword: EVENT_POOL | C38: Event(Name) | D38: Pool(Name) | E38: Source? | F38: Sequence Number | G38: Allow Recycling (Boolean)
A40: =IF($C$3="ON","","COMMENT") | B40: EVENT_POOL | C40: =$C$26 -> MCF Factoring | D40: ='Inputs - Flow Network'!C14 -> Solid Waste Disposal Site | E40: =TRUE() -> TRUE | F40: 1
A41: =IF($C$3="ON","","COMMENT") | B41: EVENT_POOL | C41: =$C$26 -> MCF Factoring | D41: =C7 -> Aerobic conditions | E41: =FALSE() -> FALSE | F41: 1
A42: =IF($C$3="ON","","COMMENT") | B42: EVENT_POOL | C42: =$C$26 -> MCF Factoring | D42: =C8 -> Anaerobic conditions | E42: =FALSE() -> FALSE | F42: 2
A43: =IF($C$3="ON","","COMMENT")
A44: =IF($C$3="ON","","COMMENT") | B44: EVENT_POOL | C44: =$C$27 -> DOCf Factoring | D44: =C8 -> Anaerobic conditions | E44: =TRUE() -> TRUE | F44: 1
A45: =IF($C$3="ON","","COMMENT") | B45: EVENT_POOL | C45: =$C$27 -> DOCf Factoring | D45: =C10 -> Decomposable | E45: =FALSE() -> FALSE | F45: 1
A46: =IF($C$3="ON","","COMMENT") | B46: EVENT_POOL | C46: =$C$27 -> DOCf Factoring | D46: =C11 -> Non-decomposable | E46: =FALSE() -> FALSE | F46: 2
A47: =IF($C$3="ON","","COMMENT")
A48: =IF($C$3="ON","","COMMENT") | B48: EVENT_POOL | C48: =$C$28 -> Climate Zoning | D48: =C10 -> Decomposable | E48: =TRUE() -> TRUE | F48: 1
...

Sheet Inputs - Carbon
B1: Keyword: INITIAL_CMO | C1: Entry Pool (Pool Name) | D1: Species (Name) | E1: Physical State (Name) | F1: Quantity (Double precison) | G1: Entry Time Step (Integer) | H1: Initial Age | I1: Tag (Name) | J1: Is Retained | K1: Description
B3: INITIAL_CMO | C3: ='Inputs - Flow Network'!$C$3 -> Roundwood | F3: =[1]Sheet1!H2 -> 37127083 | G3: 1990
B4: INITIAL_CMO | C4: ='Inputs - Flow Network'!$C$3 -> Roundwood | F4: =[1]Sheet1!H3 -> 36678472 | G4: 1991
B5: INITIAL_CMO | C5: ='Inputs - Flow Network'!$C$3 -> Roundwood | F5: =[1]Sheet1!H4 -> 38905955 | G5: 1992
B6: INITIAL_CMO | C6: ='Inputs - Flow Network'!$C$3 -> Roundwood | F6: =[1]Sheet1!H5 -> 40348197 | G6: 1993
B7: INITIAL_CMO | C7: ='Inputs - Flow Network'!$C$3 -> Roundwood | F7: =[1]Sheet1!H6 -> 41958296 | G7: 1994
B8: INITIAL_CMO | C8: ='Inputs - Flow Network'!$C$3 -> Roundwood | F8: =[1]Sheet1!H7 -> 43150928 | G8: 1995
B9: INITIAL_CMO | C9: ='Inputs - Flow Network'!$C$3 -> Roundwood | F9: =[1]Sheet1!H8 -> 43483436 | G9: 1996
B10: INITIAL_CMO | C10: ='Inputs - Flow Network'!$C$3 -> Roundwood | F10: =[1]Sheet1!H9 -> 43752282 | G10: 1997
B11: INITIAL_CMO | C11: ='Inputs - Flow Network'!$C$3 -> Roundwood | F11: =[1]Sheet1!H10 -> 40519718 | G11: 1998
B12: INITIAL_CMO | C12: ='Inputs - Flow Network'!$C$3 -> Roundwood | F12: =[1]Sheet1!H11 -> 44400810 | G12: 1999
B13: INITIAL_CMO | C13: ='Inputs - Flow Network'!$C$3 -> Roundwood | F13: =[1]Sheet1!H12 -> 46222505 | G13: 2000
B14: INITIAL_CMO | C14: ='Inputs - Flow Network'!$C$3 -> Roundwood | F14: =[1]Sheet1!H13 -> 42560337 | G14: 2001
... B37: INITIAL_CMO | C37: ='Inputs - Flow Network'!$C$3 -> Roundwood | F37: =[1]Sheet1!H36 -> 26583833 | G37: 2024

Sheet Inputs - Tags
B1: Keyword: PHYSICAL_STATE | C1: Name | D1: Description
B3: PHYSICAL_STATE | C3: Roundwood
B4: PHYSICAL_STATE | C4: Sawnwood
B5: PHYSICAL_STATE | C5: Panels
B6: PHYSICAL_STATE | C6: Paper
B7: PHYSICAL_STATE | C7: Bioenergy
B9: Keyword: PHYSICAL_STATE_GROUP | C9: Name | D9: Reference | E9: Description
B11: PHYSICAL_STATE_GROUP | C11: Less decomposable wastes
B12: PHYSICAL_STATE_GROUP | C12: Moderately decomposable wastes
B14: Keyword: PHYSICAL_STATE_GROUP_MEMBER | C14: Group(Name) | D14: Physical_State(Name)
B16: PHYSICAL_STATE_GROUP_MEMBER | C16: =C11 -> Less decomposable wastes | D16: =C4 -> Sawnwood
B17: PHYSICAL_STATE_GROUP_MEMBER | C17: =C11 -> Less decomposable wastes | D17: =C5 -> Panels
B19: PHYSICAL_STATE_GROUP_MEMBER | C19: =C12 -> Moderately decomposable wastes | D19: =C6 -> Paper
B21: Keyword: SPECIES | C21: Name | D21: Alternate_Name | E21: Code | F21: Reference | G21: Description
B23: Keyword: SPECIES_GROUP | C23: Name | D23: Reference | E23: Description
B25: Keyword: SPECIES_GROUP_MEMBER | C25: Species_Group(Name) | D25: Species(Name)
B27: Keyword: TAG | C27: Name | D27: Value | E27: Description

Sheet Inputs - Curves
B1: Keyword: CURVE | C1: Name | D1: Usage | E1: Reference | F1: Description
B3: CURVE | C3: Exponential decay, k=0.03 | F3: Boreal and Temperate, Wet, Wood
B4: CURVE | C4: Exponential decay, k=0.06 | F4: Boreal and Temperate, Wet, Paper/textiles
B6: Keyword: CURVE_TYPE | C6: Name | D6: Reference | E6: Description
B8: CURVE_TYPE | C8: Landfilled Wood Decay Curve
B9: CURVE_TYPE | C9: Landfilled Paper Decay Curve
B11: Keyword: CURVE_TYPE_MEMBER | C11: Curve_Type(Name) | D11: Curve(Name) | E11: ASU_Group(Name) | F11: Effective start timestep
B13: CURVE_TYPE_MEMBER | C13: =C8 -> Landfilled Wood Decay Curve | D13: =C3 -> Exponential decay, k=0.03 | E13: UNIVERSE | F13: 1
B14: CURVE_TYPE_MEMBER | C14: =C9 -> Landfilled Paper Decay Curve | D14: =C4 -> Exponential decay, k=0.06 | E14: UNIVERSE | F14: 1
B16: Keyword: CURVE_POINT | C16: Curve(Name) | D16: X_axis (Independent Variable) | E16: Y_axis (Dependent Variable)
B18: CURVE_POINT | C18: =$C$3 -> Exponential decay, k=0.03 | D18: 0 | E18: 1
B19: CURVE_POINT | C19: =$C$3 -> Exponential decay, k=0.03 | D19: 1 | E19: =EXP(-0.03) -> 0.97044553
B21: CURVE_POINT | C21: =C4 -> Exponential decay, k=0.06 | D21: 0 | E21: 1
B22: CURVE_POINT | C22: =C4 -> Exponential decay, k=0.06 | D22: 1 | E22: =EXP(-0.06) -> 0.94176453
