Workbook

Sheet Inputs - Flow Network
B1: Keyword: POOL | C1: Name | D1: ASU(Integer ID) | E1: Curve_Type(Name) [retention] | F1: Curve_Type(Name) [decay] | G1: ASU_ Group(Name) [retention] | H1: ASU_Group(Name) [decay] | I1: Max Capacity | J1: Allow Age Zero Flowthrough | K1: Pool_Ruleset(Name) | L1: Description/Note
B3: POOL | C3: ="Roundwood, "&'Inputs - Spatial'!$C$10 -> Roundwood, CAT | D3: ='Inputs - Spatial'!$C$2 -> 1725
B4: POOL | C4: ="Sawnwood, "&'Inputs - Spatial'!$C$10 -> Sawnwood, CAT | D4: ='Inputs - Spatial'!$C$2 -> 1725 | E4: IPCC default-sawnwood
B5: POOL | C5: ="Panels, "&'Inputs - Spatial'!$C$10 -> Panels, CAT | D5: ='Inputs - Spatial'!$C$2 -> 1725 | E5: IPCC default-panels
B6: POOL | C6: ="Paper, "&'Inputs - Spatial'!$C$10 -> Paper, CAT | D6: ='Inputs - Spatial'!$C$2 -> 1725 | E6: IPCC default-paper
B8: POOL | C8: ="Bioenergy, "&'Inputs - Spatial'!$C$10 -> Bioenergy, CAT | D8: ='Inputs - Spatial'!$C$2 -> 1725
B10: POOL | C10: ="Postconsumer Products, "&'Inputs - Spatial'!C10 -> Postconsumer Products, CAT | D10: ='Inputs - Spatial'!$C$2 -> 1725
B12: POOL | C12: ="CO2, "&'Inputs - Spatial'!$C$10 -> CO2, CAT | D12: ='Inputs - Spatial'!$C$2 -> 1725
B14: Keyword: EVENT | C14: Name | D14: Action_Type(Name) | E14: ASU(Integer ID) | F14: Curve(Name)[Quantity Cap]* | G14: Curve(Name)[Target Quantity]* | H14: First Timestep | I14: Last Timestep | J14: Event Ruleset(Name) | K14: ASU_Group(Name) | L14: Description/Note
B16: EVENT | C16: ="Commodity Manufacturing, "&'Inputs - Spatial'!C10 -> Commodity Manufacturing, CAT | D16: =C23 -> Manufacturing | E16: ='Inputs - Spatial'!$C$2 -> 1725
B17: EVENT | C17: ="Retiring, "&'Inputs - Spatial'!C10 -> Retiring, CAT | D17: =C24 -> Retiring | E17: ='Inputs - Spatial'!$C$2 -> 1725
B18: EVENT | C18: ="End of Life Cascading, "&'Inputs - Spatial'!$C$10 -> End of Life Cascading, CAT | D18: =C25 -> Cascading | E18: ='Inputs - Spatial'!$C$2 -> 1725
B19: EVENT | C19: ="Combusting, "&'Inputs - Spatial'!$C$10 -> Combusting, CAT | D19: =C26 -> Combusting | E19: ='Inputs - Spatial'!$C$2 -> 1725
B21: Keyword: ACTION_TYPE | C21: NAME
B23: ACTION_TYPE | C23: Manufacturing
B24: ACTION_TYPE | C24: Retiring
B25: ACTION_TYPE | C25: Cascading
B26: ACTION_TYPE | C26: Combusting
B29: Keyword: EVENT_POOL | C29: Event(Name) | D29: Pool(Name) | E29: Source? | F29: Sequence Number | G29: Allow Recycling (Boolean)
B31: EVENT_POOL | C31: =$C$16 -> Commodity Manufacturing, CAT | D31: =C3 -> Roundwood, CAT | E31: TRUE | F31: 1
B32: EVENT_POOL | C32: =$C$16 -> Commodity Manufacturing, CAT | D32: =C4 -> Sawnwood, CAT | E32: FALSE | F32: 1
B33: EVENT_POOL | C33: =$C$16 -> Commodity Manufacturing, CAT | D33: =C5 -> Panels, CAT | E33: FALSE | F33: 2
B34: EVENT_POOL | C34: =$C$16 -> Commodity Manufacturing, CAT | D34: =C6 -> Paper, CAT | E34: FALSE | F34: 3
B35: EVENT_POOL | C35: =$C$16 -> Commodity Manufacturing, CAT | D35: =C8 -> Bioenergy, CAT | E35: FALSE | F35: 4
B37: EVENT_POOL | C37: =$C$17 -> Retiring, CAT | D37: =C4 -> Sawnwood, CAT | E37: TRUE | F37: 1
B38: EVENT_POOL | C38: =$C$17 -> Retiring, CAT | D38: =C5 -> Panels, CAT | E38: TRUE | F38: 2
B39: EVENT_POOL | C39: =$C$17 -> Retiring, CAT | D39: =C6 -> Paper, CAT | E39: TRUE | F39: 3
B40: EVENT_POOL | C40: =$C$17 -> Retiring, CAT | D40: =C10 -> Postconsumer Products, CAT | E40: FALSE | F40: 1
B42: EVENT_POOL | C42: {=$C$18} -> End of Life Cascading, CAT | D42: =C10 -> Postconsumer Products, CAT | E42: TRUE | F42: 1
B43: EVENT_POOL | C43: {=$C$18} -> End of Life Cascading, CAT | D43: =C4 -> Sawnwood, CAT | E43: FALSE | F43: 1 | G43: TRUE
B44: EVENT_POOL | C44: {=$C$18} -> End of Life Cascading, CAT | D44: =C5 -> Panels, CAT | E44: FALSE | F44: 2 | G44: TRUE
B45: EVENT_POOL | C45: {=$C$18} -> End of Life Cascading, CAT | D45: =C6 -> Paper, CAT | E45: FALSE | F45: 3 | G45: TRUE
B46: EVENT_POOL | C46: {=$C$18} -> End of Life Cascading, CAT | D46: =C12 -> CO2, CAT | E46: FALSE | F46: 4
B48: EVENT_POOL | C48: =$C$19 -> Combusting, CAT | D48: =C8 -> Bioenergy, CAT | E48: TRUE | F48: 1
B49: EVENT_POOL | C49: =$C$19 -> Combusting, CAT | D49: =C12 -> CO2, CAT | E49: FALSE | F49: 1
B51: Keyword: ACTION_PARAMETER_SET | C51: Name | D51: Action_Type (Name) | E51: ASU_Group(Name) | F51: Effective Start Timestep* | G51: Reference | H51: Description
B53: ACTION_PARAMETER_SET | C53: ="Commodity Recovery Shares, "&'Inputs - Spatial'!$C$10 -> Commodity Recovery Shares, CAT | D53: =C23 -> Manufacturing | E53: ='Inputs - Spatial'!$C$10 -> CAT
B54: ACTION_PARAMETER_SET | C54: ="Commodity Retiring, "&'Inputs - Spatial'!$C$10 -> Commodity Retiring, CAT | D54: =D17 -> Retiring | E54: ='Inputs - Spatial'!$C$10 -> CAT
B55: ACTION_PARAMETER_SET | C55: ="End of Life Practices, "&'Inputs - Spatial'!$C$10 -> End of Life Practices, CAT | D55: =C25 -> Cascading | E55: ='Inputs - Spatial'!$C$10 -> CAT
B56: ACTION_PARAMETER_SET | C56: ="Combustion Parameters, "&'Inputs - Spatial'!$C$10 -> Combustion Parameters, CAT | D56: =C26 -> Combusting | E56: ='Inputs - Spatial'!$C$10 -> CAT
...

Sheet Inputs - Carbon Mass
B1: Keyword: INITIAL_CMO | C1: Entry Pool (Pool Name) | D1: Species (Name) | E1: Physical State (Name) | F1: Quantity (Double precison) | G1: Entry Time Step (Integer) | H1: Initial Age | I1: Tag (Name) | J1: Is Retained | K1: Description
B2: INITIAL_CMO | C2: ='Inputs - Flow Network'!$C$3 -> Roundwood, CAT | D2: ='Inputs - Categorical'!C15 -> Softwood | F2: 100 | G2: 1 | K2: 1990
B3: INITIAL_CMO | C3: ='Inputs - Flow Network'!$C$3 -> Roundwood, CAT | D3: ='Inputs - Categorical'!C16 -> Hardwood | F3: 100 | G3: 1 | K3: 1990

Sheet Inputs - Categorical
B1: Keyword: PHYSICAL_STATE | C1: Name | D1: Description
B3: PHYSICAL_STATE | C3: Roundwood
B4: PHYSICAL_STATE | C4: Sawnwood
B5: PHYSICAL_STATE | C5: Panels
B6: PHYSICAL_STATE | C6: Paper
B7: PHYSICAL_STATE | C7: Bioenergy
B9: Keyword: PHYSICAL_STATE_GROUP | C9: Name | D9: Reference | E9: Description
B11: Keyword: PHYSICAL_STATE_GROUP_MEMBER | C11: Group(Name) | D11: Physical_State(Name)
B13: Keyword: SPECIES | C13: Name | D13: Alternate_Name | E13: Code | F13: Reference | G13: Description
B15: SPECIES | C15: Softwood
B16: SPECIES | C16: Hardwood
B18: Keyword: SPECIES_GROUP | C18: Name | D18: Reference | E18: Description
B20: Keyword: SPECIES_GROUP_MEMBER | C20: Species_Group(Name) | D20: Species(Name)
B22: Keyword: TAG | C22: Name | D22: Value | E22: Description

Sheet Inputs - Spatial
B1: Keyword: ASU | C1: ID | D1: Name | E1: Area | F1: Tag(Name) | G1: GIS_Id | H1: Description
B2: ASU | C2: 1725 | D2: CAT | E2: 998
B5: Keyword: ASU_GROUP_TYPE | C5: Name
B6: ASU_GROUP_TYPE | C6: Company
B8: Keyword: ASU_GROUP | C8: Name | D8: ASU_Group_Type(Name) | E8: Description
B10: ASU_GROUP | C10: CAT | D10: =C6 -> Company
B13: Keyword: ASU_GROUP_MEMBER | C13: ASU_Group(Name) | D13: ASU(ID) | E13: Includes: ASU_Group(Name)
B14: ASU_GROUP_MEMBER | C14: =C10 -> CAT | D14: =C2 -> 1725

Sheet Inputs - Advanced Curves
B1: Keyword: CURVE | C1: Name | D1: Usage | E1: Reference | F1: Description
B3: CURVE | C3: Gamma (2.07 80.2) | D3: initial | E3: Xie, 2015
B7: Keyword: CURVE_TYPE | C7: Name | D7: Reference | E7: Description
B9: CURVE_TYPE | C9: US Residential Gamma Retention
B12: Keyword: CURVE_TYPE_MEMBER | C12: Curve_Type(Name) | D12: Curve(Name) | E12: ASU_Group(Name) | F12: Effective start timestep
B14: CURVE_TYPE_MEMBER | C14: =C9 -> US Residential Gamma Retention | D14: =C3 -> Gamma (2.07 80.2) | E14: UNIVERSE | F14: 1
B19: Keyword: CURVE_POINT | C19: Curve(Name) | D19: X_axis (Independent Variable) | E19: Y_axis (Dependent Variable)
B21: CURVE_POINT | C21: =$C$3 -> Gamma (2.07 80.2) | D21: 0 | E21: 1
B22: CURVE_POINT | C22: =$C$3 -> Gamma (2.07 80.2) | D22: 1 | E22: 0.99994689
B23: CURVE_POINT | C23: =$C$3 -> Gamma (2.07 80.2) | D23: 2 | E23: 0.99977885
B24: CURVE_POINT | C24: =$C$3 -> Gamma (2.07 80.2) | D24: 3 | E24: 0.99949235
B25: CURVE_POINT | C25: =$C$3 -> Gamma (2.07 80.2) | D25: 4 | E25: 0.99908684
B26: CURVE_POINT | C26: =$C$3 -> Gamma (2.07 80.2) | D26: 5 | E26: 0.9985628
B27: CURVE_POINT | C27: =$C$3 -> Gamma (2.07 80.2) | D27: 6 | E27: 0.9979213
B28: CURVE_POINT | C28: =$C$3 -> Gamma (2.07 80.2) | D28: 7 | E28: 0.99716376
B29: CURVE_POINT | C29: =$C$3 -> Gamma (2.07 80.2) | D29: 8 | E29: 0.9962918
B30: CURVE_POINT | C30: =$C$3 -> Gamma (2.07 80.2) | D30: 9 | E30: 0.99530724
B31: CURVE_POINT | C31: =$C$3 -> Gamma (2.07 80.2) | D31: 10 | E31: 0.99421198
B32: CURVE_POINT | C32: =$C$3 -> Gamma (2.07 80.2) | D32: 11 | E32: 0.99300802
... B321: CURVE_POINT | C321: =$C$3 -> Gamma (2.07 80.2) | D321: 300 | E321: 0.1218235
