Workbook

Sheet Inputs - Flow Network
B1: Keyword: POOL | C1: Name | D1: ASU(Integer ID) | E1: Curve_Type(Name) [retention] | F1: Curve_Type(Name) [decay] | G1: ASU_ Group(Name) [retention] | H1: ASU_Group(Name) [decay] | I1: Max Capacity | J1: Allow Age Zero Flowthrough | K1: Pool_Ruleset(Name) | L1: Description/Note
B3: POOL | C3: ="Roundwood, "&'Inputs - Spatial'!$C$10 -> Roundwood, CAT | D3: ='Inputs - Spatial'!$C$2 -> 1725
B4: POOL | C4: ="Sawnwood, "&'Inputs - Spatial'!$C$10 -> Sawnwood, CAT | D4: ='Inputs - Spatial'!$C$2 -> 1725 | E4: IPCC default-sawnwood
B5: POOL | C5: ="Panels, "&'Inputs - Spatial'!$C$10 -> Panels, CAT | D5: ='Inputs - Spatial'!$C$2 -> 1725 | E5: IPCC default-panels
B6: POOL | C6: ="Paper, "&'Inputs - Spatial'!$C$10 -> Paper, CAT | D6: ='Inputs - Spatial'!$C$2 -> 1725 | E6: IPCC default-paper
B8: POOL | C8: ="Bioenergy, "&'Inputs - Spatial'!$C$10 -> Bioenergy, CAT | D8: ='Inputs - Spatial'!$C$2 -> 1725
B10: POOL | C10: ="CO2, "&'Inputs - Spatial'!$C$10 -> CO2, CAT | D10: ='Inputs - Spatial'!$C$2 -> 1725
B12: Keyword: EVENT | C12: Name | D12: Action_Type(Name) | E12: ASU(Integer ID) | F12: Curve(Name)[Quantity Cap]* | G12: Curve(Name)[Target Quantity]* | H12: First Timestep | I12: Last Timestep | J12: Event Ruleset(Name) | K12: ASU_Group(Name) | L12: Description/Note
B14: EVENT | C14: ="Manufacturing, "&'Inputs - Spatial'!C10 -> Manufacturing, CAT | E14: ='Inputs - Spatial'!$C$2 -> 1725
B15: EVENT | C15: ="Landfilling, "&'Inputs - Spatial'!$C$10 -> Landfilling, CAT | E15: ='Inputs - Spatial'!$C$2 -> 1725
B16: EVENT | C16: ="Combusting, "&'Inputs - Spatial'!$C$10 -> Combusting, CAT | E16: ='Inputs - Spatial'!$C$2 -> 1725
B18: Keyword: EVENT_POOL | C18: Event(Name) | D18: Pool(Name) | E18: Source? | F18: Sequence Number | G18: Allow Recycling (Boolean)
B20: EVENT_POOL | C20: =$C$14 -> Manufacturing, CAT | D20: =C3 -> Roundwood, CAT | E20: TRUE | F20: 1
B21: EVENT_POOL | C21: =$C$14 -> Manufacturing, CAT | D21: =C4 -> Sawnwood, CAT | E21: FALSE | F21: 1
B22: EVENT_POOL | C22: =$C$14 -> Manufacturing, CAT | D22: =C5 -> Panels, CAT | E22: FALSE | F22: 2
B23: EVENT_POOL | C23: =$C$14 -> Manufacturing, CAT | D23: =C6 -> Paper, CAT | E23: FALSE | F23: 3
B24: EVENT_POOL | C24: =$C$14 -> Manufacturing, CAT | D24: =C8 -> Bioenergy, CAT | E24: FALSE | F24: 4
B26: EVENT_POOL | C26: {=$C$15} -> Landfilling, CAT | D26: =C4 -> Sawnwood, CAT | E26: TRUE | F26: 1
B27: EVENT_POOL | C27: {=$C$15} -> Landfilling, CAT | D27: =C5 -> Panels, CAT | E27: TRUE | F27: 2
B28: EVENT_POOL | C28: {=$C$15} -> Landfilling, CAT | D28: =C6 -> Paper, CAT | E28: TRUE | F28: 3
B29: EVENT_POOL | C29: {=$C$15} -> Landfilling, CAT | D29: =C10 -> CO2, CAT | E29: FALSE | F29: 1
B31: EVENT_POOL | C31: =$C$16 -> Combusting, CAT | D31: =C8 -> Bioenergy, CAT | E31: TRUE | F31: 1
B32: EVENT_POOL | C32: =$C$16 -> Combusting, CAT | D32: =C10 -> CO2, CAT | E32: FALSE | F32: 1
B34: Keyword: ACTION_PARAMETER_OUT | C34: Action_Parameter_Set | D34: Sequence Number | E34: Proportion | F34: Target | G34: New Physical State Name | H34: Physical State Rule | I34: Species Rule | J34: Note
B36: ACTION_PARAMETER_OUT | C36: =$C$21 -> Manufacturing, CAT | D36: =$F$21 -> 1 | E36: 0.4 | I36: ='Inputs - Categorical'!$C$19 -> SPF
B37: ACTION_PARAMETER_OUT | C37: =$C$22 -> Manufacturing, CAT | D37: =$F$22 -> 2 | E37: 0 | I37: ='Inputs - Categorical'!$C$19 -> SPF
B38: ACTION_PARAMETER_OUT | C38: =$C$23 -> Manufacturing, CAT | D38: =$F$23 -> 3 | E38: 0.25 | I38: ='Inputs - Categorical'!$C$19 -> SPF
B39: ACTION_PARAMETER_OUT | C39: =$C$24 -> Manufacturing, CAT | D39: =$F$24 -> 4 | E39: 0.35 | I39: ='Inputs - Categorical'!$C$19 -> SPF
B41: ACTION_PARAMETER_OUT | C41: =$C$21 -> Manufacturing, CAT | D41: =$F$21 -> 1 | E41: 0 | I41: ='Inputs - Categorical'!$C$20 -> Hardwood
B42: ACTION_PARAMETER_OUT | C42: =$C$22 -> Manufacturing, CAT | D42: =$F$22 -> 2 | E42: 0.4 | I42: ='Inputs - Categorical'!$C$20 -> Hardwood
B43: ACTION_PARAMETER_OUT | C43: =$C$23 -> Manufacturing, CAT | D43: =$F$23 -> 3 | E43: 0.25 | I43: ='Inputs - Categorical'!$C$20 -> Hardwood
B44: ACTION_PARAMETER_OUT | C44: =$C$24 -> Manufacturing, CAT | D44: =$F$24 -> 4 | E44: 0.35 | I44: ='Inputs - Categorical'!$C$20 -> Hardwood
B46: ACTION_PARAMETER_OUT | C46: =$C$21 -> Manufacturing, CAT | D46: =$F$21 -> 1 | E46: 0.35 | I46: ='Inputs - Categorical'!$C$21 -> Hem-Fir
B47: ACTION_PARAMETER_OUT | C47: =$C$22 -> Manufacturing, CAT | D47: =$F$22 -> 2 | E47: 0 | I47: ='Inputs - Categorical'!$C$21 -> Hem-Fir
B48: ACTION_PARAMETER_OUT | C48: =$C$23 -> Manufacturing, CAT | D48: =$F$23 -> 3 | E48: 0.25 | I48: ='Inputs - Categorical'!$C$21 -> Hem-Fir
B49: ACTION_PARAMETER_OUT | C49: =$C$24 -> Manufacturing, CAT | D49: =$F$24 -> 4 | E49: 0.4 | I49: ='Inputs - Categorical'!$C$21 -> Hem-Fir
B51: ACTION_PARAMETER_OUT | C51: =$C$21 -> Manufacturing, CAT | D51: =F21 -> 1 | E51: 0.45 | I51: ='Inputs - Categorical'!$C$22 -> DFL
B52: ACTION_PARAMETER_OUT | C52: =$C$22 -> Manufacturing, CAT | D52: =F22 -> 2 | E52: 0.15 | I52: ='Inputs - Categorical'!$C$22 -> DFL
B53: ACTION_PARAMETER_OUT | C53: =$C$23 -> Manufacturing, CAT | D53: =F23 -> 3 | E53: 0.15 | I53: ='Inputs - Categorical'!$C$22 -> DFL
B54: ACTION_PARAMETER_OUT | C54: =$C$24 -> Manufacturing, CAT | D54: =F24 -> 4 | E54: 0.25 | I54: ='Inputs - Categorical'!$C$22 -> DFL
...

Sheet Inputs - Carbon Mass
B1: Keyword: INITIAL_CMO | C1: Entry Pool (Pool Name) | D1: Species (Name) | E1: Physical State (Name) | F1: Quantity (Double precison) | G1: Entry Time Step (Integer) | H1: Initial Age | I1: Tag (Name) | J1: Is Retained | K1: Description
B2: INITIAL_CMO | C2: ='Inputs - Flow Network'!$C$3 -> Roundwood, CAT | D2: ='Inputs - Categorical'!C9 -> Spruce | F2: 100 | G2: 1 | K2: 1990
B3: INITIAL_CMO | C3: ='Inputs - Flow Network'!$C$3 -> Roundwood, CAT | D3: ='Inputs - Categorical'!C10 -> Pine | F3: 100 | G3: 1 | K3: 1990
B4: INITIAL_CMO | C4: ='Inputs - Flow Network'!$C$3 -> Roundwood, CAT | D4: ='Inputs - Categorical'!C11 -> Fir | F4: 100 | G4: 1 | K4: 1990
B5: INITIAL_CMO | C5: ='Inputs - Flow Network'!$C$3 -> Roundwood, CAT | D5: ='Inputs - Categorical'!C12 -> Hemlock | F5: 100 | G5: 1 | K5: 1990
B6: INITIAL_CMO | C6: ='Inputs - Flow Network'!$C$3 -> Roundwood, CAT | D6: ='Inputs - Categorical'!C13 -> Douglas-fir | F6: 100 | G6: 1 | K6: 1990
B7: INITIAL_CMO | C7: ='Inputs - Flow Network'!$C$3 -> Roundwood, CAT | D7: ='Inputs - Categorical'!C14 -> Larch | F7: 100 | G7: 1 | K7: 1990
B8: INITIAL_CMO | C8: ='Inputs - Flow Network'!$C$3 -> Roundwood, CAT | D8: ='Inputs - Categorical'!C15 -> Aspen | F8: 100 | G8: 1 | K8: 1990

Sheet Inputs - Categorical
B1: Keyword: PHYSICAL_STATE | C1: Name | D1: Description
B3: Keyword: PHYSICAL_STATE_GROUP | C3: Name | D3: Reference | E3: Description
B5: Keyword: PHYSICAL_STATE_GROUP_MEMBER | C5: Group(Name) | D5: Physical_State(Name)
B7: Keyword: SPECIES | C7: Name | D7: Alternate_Name | E7: Code | F7: Reference | G7: Description
B9: SPECIES | C9: Spruce
B10: SPECIES | C10: Pine
B11: SPECIES | C11: Fir
B12: SPECIES | C12: Hemlock
B13: SPECIES | C13: Douglas-fir
B14: SPECIES | C14: Larch
B15: SPECIES | C15: Aspen
B17: Keyword: SPECIES_GROUP | C17: Name | D17: Reference | E17: Description
B19: SPECIES_GROUP | C19: SPF
B20: SPECIES_GROUP | C20: Hardwood
B21: SPECIES_GROUP | C21: Hem-Fir
B22: SPECIES_GROUP | C22: DFL
B24: Keyword: SPECIES_GROUP_MEMBER | C24: Species_Group(Name) | D24: Species(Name)
B26: SPECIES_GROUP_MEMBER | C26: =$C$19 -> SPF | D26: =C9 -> Spruce
B27: SPECIES_GROUP_MEMBER | C27: =$C$19 -> SPF | D27: =C10 -> Pine
B28: SPECIES_GROUP_MEMBER | C28: =$C$19 -> SPF | D28: =C11 -> Fir
B30: SPECIES_GROUP_MEMBER | C30: =C20 -> Hardwood | D30: =C15 -> Aspen
B32: SPECIES_GROUP_MEMBER | C32: =C21 -> Hem-Fir | D32: =C12 -> Hemlock
B34: SPECIES_GROUP_MEMBER | C34: =$C$22 -> DFL | D34: =C13 -> Douglas-fir
B35: SPECIES_GROUP_MEMBER | C35: =$C$22 -> DFL | D35: =C14 -> Larch
B37: Keyword: TAG | C37: Name | D37: Value | E37: Description

Sheet Inputs - Spatial
B1: Keyword: ASU | C1: ID | D1: Name | E1: Area | F1: Tag(Name) | G1: GIS_Id | H1: Description
B2: ASU | C2: 1725 | D2: CAT | E2: 998
B5: Keyword: ASU_GROUP_TYPE | C5: Name
B6: ASU_GROUP_TYPE | C6: Company
B8: Keyword: ASU_GROUP | C8: Name | D8: ASU_Group_Type(Name) | E8: Description
B10: ASU_GROUP | C10: CAT | D10: =C6 -> Company
B13: Keyword: ASU_GROUP_MEMBER | C13: ASU_Group(Name) | D13: ASU(ID) | E13: Includes: ASU_Group(Name)
B14: ASU_GROUP_MEMBER | C14: =C10 -> CAT | D14: =C2 -> 1725
